Workbook

Sheet Dashboard
A1: ARITZIA-INSPIRED BUYER DASHBOARD
A2: Product Performance • Inventory • Pricing • Merchandising
A4: TOTAL INVENTORY | E4: PRODUCTS | I4: AVG PRICE | M4: AVG MARKDOWN | Q4: RETURN RATE
A5: =TotalInventory -> 54265 | E5: =TotalProducts -> 2176 | I5: =AvgCurrentPrice -> 85.499596 | M5: =OverallAvgMarkdown -> 12.144715 | Q5: =OverallReturnRate -> 0.14705882
A9: Category Snapshot (select a category): | E9: Accessories
A10: Total Stock (this category) | E10: =INDEX('Pivot Summaries'!$B$3:$B$8,MATCH($E$9,'Pivot Summaries'!$A$3:$A$8,0)) -> 10541
A11: Return Rate (this category) | E11: =INDEX('Pivot Summaries'!$B$26:$B$31,MATCH($E$9,'Pivot Summaries'!$A$26:$A$31,0)) -> 0.13681592
A13: Buyer Attention
A14: Alert | B14: Count | C14: Recommendation
A15: Overstock Review | B15: =COUNTIFS('Raw Data'!$O$2:$O$2177,"High",'Raw Data'!$P$2:$P$2177,"High") -> 188 | C15: High stock + high markdown. Review for potential overstock.
A16: Low Inventory | B16: =COUNTIF('Raw Data'!$O$2:$O$2177,"Low") -> 775 | C16: Stock in bottom tercile. Monitor availability.
A17: Markdown Review | B17: =COUNTIF('Pivot Summaries'!$B$12:$B$15,">"&OverallAvgMarkdown) -> 1 | C17: Season(s) above overall avg markdown (highlighted in Pivot Summaries). Review markdown strategy.
A18: Return Review | B18: =COUNTIF('Pivot Summaries'!$B$26:$B$31,">"&OverallReturnRate) -> 4 | C18: Categories above overall return rate (highlighted in Pivot Summaries). Review product/return patterns.

Sheet Pivot Summaries
A1: Inventory by Category
A2: Category | B2: Total Stock Quantity
A3: Accessories | B3: =SUMIFS('Raw Data'!$K$2:$K$2177,'Raw Data'!$B$2:$B$2177,A3) -> 10541
A4: Bottoms | B4: =SUMIFS('Raw Data'!$K$2:$K$2177,'Raw Data'!$B$2:$B$2177,A4) -> 9442
A5: Dresses | B5: =SUMIFS('Raw Data'!$K$2:$K$2177,'Raw Data'!$B$2:$B$2177,A5) -> 7928
A6: Outerwear | B6: =SUMIFS('Raw Data'!$K$2:$K$2177,'Raw Data'!$B$2:$B$2177,A6) -> 8368
A7: Shoes | B7: =SUMIFS('Raw Data'!$K$2:$K$2177,'Raw Data'!$B$2:$B$2177,A7) -> 9118
A8: Tops | B8: =SUMIFS('Raw Data'!$K$2:$K$2177,'Raw Data'!$B$2:$B$2177,A8) -> 8868
A10: Average Markdown by Season
A11: Season | B11: Avg Markdown %
A12: Spring | B12: =AVERAGEIFS('Raw Data'!$H$2:$H$2177,'Raw Data'!$D$2:$D$2177,A12) -> 11.839439
A13: Summer | B13: =AVERAGEIFS('Raw Data'!$H$2:$H$2177,'Raw Data'!$D$2:$D$2177,A13) -> 12.492348
A14: Fall | B14: =AVERAGEIFS('Raw Data'!$H$2:$H$2177,'Raw Data'!$D$2:$D$2177,A14) -> 12.09614
A15: Winter | B15: =AVERAGEIFS('Raw Data'!$H$2:$H$2177,'Raw Data'!$D$2:$D$2177,A15) -> 12.125287
A17: Inventory by Season
A18: Season | B18: Total Stock Quantity
A19: Spring | B19: =SUMIFS('Raw Data'!$K$2:$K$2177,'Raw Data'!$D$2:$D$2177,A19) -> 13720
A20: Summer | B20: =SUMIFS('Raw Data'!$K$2:$K$2177,'Raw Data'!$D$2:$D$2177,A20) -> 14307
A21: Fall | B21: =SUMIFS('Raw Data'!$K$2:$K$2177,'Raw Data'!$D$2:$D$2177,A21) -> 13448
A22: Winter | B22: =SUMIFS('Raw Data'!$K$2:$K$2177,'Raw Data'!$D$2:$D$2177,A22) -> 12790
A24: Return Rate by Category
A25: Category | B25: Return Rate
A26: Accessories | B26: =COUNTIFS('Raw Data'!$B$2:$B$2177,A26,'Raw Data'!$M$2:$M$2177,TRUE())/COUNTIFS('Raw Data'!$B$2:$B$2177,A26) -> 0.13681592
A27: Bottoms | B27: =COUNTIFS('Raw Data'!$B$2:$B$2177,A27,'Raw Data'!$M$2:$M$2177,TRUE())/COUNTIFS('Raw Data'!$B$2:$B$2177,A27) -> 0.15816327
A28: Dresses | B28: =COUNTIFS('Raw Data'!$B$2:$B$2177,A28,'Raw Data'!$M$2:$M$2177,TRUE())/COUNTIFS('Raw Data'!$B$2:$B$2177,A28) -> 0.14826498
A29: Outerwear | B29: =COUNTIFS('Raw Data'!$B$2:$B$2177,A29,'Raw Data'!$M$2:$M$2177,TRUE())/COUNTIFS('Raw Data'!$B$2:$B$2177,A29) -> 0.16167665
A30: Shoes | B30: =COUNTIFS('Raw Data'!$B$2:$B$2177,A30,'Raw Data'!$M$2:$M$2177,TRUE())/COUNTIFS('Raw Data'!$B$2:$B$2177,A30) -> 0.15053763
A31: Tops | B31: =COUNTIFS('Raw Data'!$B$2:$B$2177,A31,'Raw Data'!$M$2:$M$2177,TRUE())/COUNTIFS('Raw Data'!$B$2:$B$2177,A31) -> 0.1281337
A33: Buyer Recommendation Counts
A34: Recommendation | B34: Product Count
A35: BUY / PRIORITIZE | B35: =COUNTIF('Raw Data'!$R$2:$R$2177,A35) -> 105
A36: HOLD / REVIEW | B36: =COUNTIF('Raw Data'!$R$2:$R$2177,A36) -> 61
A37: MONITOR | B37: =COUNTIF('Raw Data'!$R$2:$R$2177,A37) -> 2010
A39: Top 10 Products by Inventory
A40: Product | B40: Category | C40: Brand | D40: Stock Quantity | E40: Current Price | F40: Markdown %
A41: =INDEX('Raw Data'!$A$2:$A$2177,MATCH(LARGE('Raw Data'!$S$2:$S$2177,1),'Raw Data'!$S$2:$S$2177,0)) -> FB002157 | B41: =INDEX('Raw Data'!$B$2:$B$2177,MATCH(LARGE('Raw Data'!$S$2:$S$2177,1),'Raw Data'!$S$2:$S$2177,0)) -> Dresses | C41: =INDEX('Raw Data'!$C$2:$C$2177,MATCH(LARGE('Raw Data'!$S$2:$S$2177,1),'Raw Data'!$S$2:$S$2177,0)) -> Forever21 | D41: =INDEX('Raw Data'!$K$2:$K$2177,MATCH(LARGE('Raw Data'!$S$2:$S$2177,1),'Raw Data'!$S$2:$S$2177,0)) -> 50 | E41: =INDEX('Raw Data'!$I$2:$I$2177,MATCH(LARGE('Raw Data'!$S$2:$S$2177,1),'Raw Data'!$S$2:$S$2177,0)) -> 154.11 | F41: =INDEX('Raw Data'!$H$2:$H$2177,MATCH(LARGE('Raw Data'!$S$2:$S$2177,1),'Raw Data'!$S$2:$S$2177,0)) -> 0
A42: =INDEX('Raw Data'!$A$2:$A$2177,MATCH(LARGE('Raw Data'!$S$2:$S$2177,2),'Raw Data'!$S$2:$S$2177,0)) -> FB001987 | B42: =INDEX('Raw Data'!$B$2:$B$2177,MATCH(LARGE('Raw Data'!$S$2:$S$2177,2),'Raw Data'!$S$2:$S$2177,0)) -> Accessories | C42: =INDEX('Raw Data'!$C$2:$C$2177,MATCH(LARGE('Raw Data'!$S$2:$S$2177,2),'Raw Data'!$S$2:$S$2177,0)) -> Uniqlo | D42: =INDEX('Raw Data'!$K$2:$K$2177,MATCH(LARGE('Raw Data'!$S$2:$S$2177,2),'Raw Data'!$S$2:$S$2177,0)) -> 50 | E42: =INDEX('Raw Data'!$I$2:$I$2177,MATCH(LARGE('Raw Data'!$S$2:$S$2177,2),'Raw Data'!$S$2:$S$2177,0)) -> 33 | F42: =INDEX('Raw Data'!$H$2:$H$2177,MATCH(LARGE('Raw Data'!$S$2:$S$2177,2),'Raw Data'!$S$2:$S$2177,0)) -> 0
A43: =INDEX('Raw Data'!$A$2:$A$2177,MATCH(LARGE('Raw Data'!$S$2:$S$2177,3),'Raw Data'!$S$2:$S$2177,0)) -> FB001892 | B43: =INDEX('Raw Data'!$B$2:$B$2177,MATCH(LARGE('Raw Data'!$S$2:$S$2177,3),'Raw Data'!$S$2:$S$2177,0)) -> Outerwear | C43: =INDEX('Raw Data'!$C$2:$C$2177,MATCH(LARGE('Raw Data'!$S$2:$S$2177,3),'Raw Data'!$S$2:$S$2177,0)) -> Forever21 | D43: =INDEX('Raw Data'!$K$2:$K$2177,MATCH(LARGE('Raw Data'!$S$2:$S$2177,3),'Raw Data'!$S$2:$S$2177,0)) -> 50 | E43: =INDEX('Raw Data'!$I$2:$I$2177,MATCH(LARGE('Raw Data'!$S$2:$S$2177,3),'Raw Data'!$S$2:$S$2177,0)) -> 182.4 | F43: =INDEX('Raw Data'!$H$2:$H$2177,MATCH(LARGE('Raw Data'!$S$2:$S$2177,3),'Raw Data'!$S$2:$S$2177,0)) -> 18.9
A44: =INDEX('Raw Data'!$A$2:$A$2177,MATCH(LARGE('Raw Data'!$S$2:$S$2177,4),'Raw Data'!$S$2:$S$2177,0)) -> FB001881 | B44: =INDEX('Raw Data'!$B$2:$B$2177,MATCH(LARGE('Raw Data'!$S$2:$S$2177,4),'Raw Data'!$S$2:$S$2177,0)) -> Accessories | C44: =INDEX('Raw Data'!$C$2:$C$2177,MATCH(LARGE('Raw Data'!$S$2:$S$2177,4),'Raw Data'!$S$2:$S$2177,0)) -> H&M | D44: =INDEX('Raw Data'!$K$2:$K$2177,MATCH(LARGE('Raw Data'!$S$2:$S$2177,4),'Raw Data'!$S$2:$S$2177,0)) -> 50 | E44: =INDEX('Raw Data'!$I$2:$I$2177,MATCH(LARGE('Raw Data'!$S$2:$S$2177,4),'Raw Data'!$S$2:$S$2177,0)) -> 52.57 | F44: =INDEX('Raw Data'!$H$2:$H$2177,MATCH(LARGE('Raw Data'!$S$2:$S$2177,4),'Raw Data'!$S$2:$S$2177,0)) -> 0
A45: =INDEX('Raw Data'!$A$2:$A$2177,MATCH(LARGE('Raw Data'!$S$2:$S$2177,5),'Raw Data'!$S$2:$S$2177,0)) -> FB001857 | B45: =INDEX('Raw Data'!$B$2:$B$2177,MATCH(LARGE('Raw Data'!$S$2:$S$2177,5),'Raw Data'!$S$2:$S$2177,0)) -> Bottoms | C45: =INDEX('Raw Data'!$C$2:$C$2177,MATCH(LARGE('Raw Data'!$S$2:$S$2177,5),'Raw Data'!$S$2:$S$2177,0)) -> Mango | D45: =INDEX('Raw Data'!$K$2:$K$2177,MATCH(LARGE('Raw Data'!$S$2:$S$2177,5),'Raw Data'!$S$2:$S$2177,0)) -> 50 | E45: =INDEX('Raw Data'!$I$2:$I$2177,MATCH(LARGE('Raw Data'!$S$2:$S$2177,5),'Raw Data'!$S$2:$S$2177,0)) -> 108.89 | F45: =INDEX('Raw Data'!$H$2:$H$2177,MATCH(LARGE('Raw Data'!$S$2:$S$2177,5),'Raw Data'!$S$2:$S$2177,0)) -> 0
...

Sheet Raw Data
A1: product_id | B1: category | C1: brand | D1: season | E1: size | F1: color | G1: original_price | H1: markdown_percentage | I1: current_price | J1: purchase_date | K1: stock_quantity | L1: customer_rating | M1: is_returned | N1: return_reason | O1: stock_tier | P1: markdown_tier | Q1: rating_tier | R1: buyer_recommendation | S1: rank_key
A2: FB000001 | B2: Outerwear | C2: Zara | D2: Spring | E2: XL | F2: Red | G2: 196.01 | H2: 0 | I2: 196.01 | J2: 2025-07-05 | K2: 37 | L2: 3 | M2: =FALSE() -> FALSE | O2: =IF(K2<=StockP33,"Low",IF(K2<=StockP67,"Moderate","High")) -> High | P2: =IF(H2=0,"Low",IF(H2<=MarkdownP75,"Moderate","High")) -> Low | Q2: =IF(ISBLANK(L2),"Unknown",IF(L2>=4,"Good",IF(L2<=2,"Poor","Neutral"))) -> Neutral | R2: =IF(AND(O2="Low",P2="Low",Q2="Good"),"BUY / PRIORITIZE",IF(AND(O2="High",P2="High",OR(Q2="Poor",M2=TRUE())),"HOLD / REVIEW","MONITOR")) -> MONITOR | S2: =K2+(ROW()/10000000) -> 37
A3: FB000002 | B3: Tops | C3: Uniqlo | D3: Winter | E3: L | F3: Pink | G3: 119.64 | H3: 0 | I3: 119.64 | J3: 2025-08-06 | K3: 2 | L3: 2.5 | M3: =FALSE() -> FALSE | O3: =IF(K3<=StockP33,"Low",IF(K3<=StockP67,"Moderate","High")) -> Low | P3: =IF(H3=0,"Low",IF(H3<=MarkdownP75,"Moderate","High")) -> Low | Q3: =IF(ISBLANK(L3),"Unknown",IF(L3>=4,"Good",IF(L3<=2,"Poor","Neutral"))) -> Neutral | R3: =IF(AND(O3="Low",P3="Low",Q3="Good"),"BUY / PRIORITIZE",IF(AND(O3="High",P3="High",OR(Q3="Poor",M3=TRUE())),"HOLD / REVIEW","MONITOR")) -> MONITOR | S3: =K3+(ROW()/10000000) -> 2.0000003
A4: FB000003 | B4: Accessories | C4: Uniqlo | D4: Winter | F4: Black | G4: 33.8 | H4: 0 | I4: 33.8 | J4: 2025-08-06 | K4: 22 | L4: 4.3 | M4: =FALSE() -> FALSE | O4: =IF(K4<=StockP33,"Low",IF(K4<=StockP67,"Moderate","High")) -> Moderate | P4: =IF(H4=0,"Low",IF(H4<=MarkdownP75,"Moderate","High")) -> Low | Q4: =IF(ISBLANK(L4),"Unknown",IF(L4>=4,"Good",IF(L4<=2,"Poor","Neutral"))) -> Good | R4: =IF(AND(O4="Low",P4="Low",Q4="Good"),"BUY / PRIORITIZE",IF(AND(O4="High",P4="High",OR(Q4="Poor",M4=TRUE())),"HOLD / REVIEW","MONITOR")) -> MONITOR | S4: =K4+(ROW()/10000000) -> 22
A5: FB000004 | B5: Shoes | C5: Uniqlo | D5: Spring | E5: XL | F5: Black | G5: 75.36 | H5: 0 | I5: 75.36 | J5: 2025-07-07 | K5: 48 | L5: 2.6 | M5: =FALSE() -> FALSE | O5: =IF(K5<=StockP33,"Low",IF(K5<=StockP67,"Moderate","High")) -> High | P5: =IF(H5=0,"Low",IF(H5<=MarkdownP75,"Moderate","High")) -> Low | Q5: =IF(ISBLANK(L5),"Unknown",IF(L5>=4,"Good",IF(L5<=2,"Poor","Neutral"))) -> Neutral | R5: =IF(AND(O5="Low",P5="Low",Q5="Good"),"BUY / PRIORITIZE",IF(AND(O5="High",P5="High",OR(Q5="Poor",M5=TRUE())),"HOLD / REVIEW","MONITOR")) -> MONITOR | S5: =K5+(ROW()/10000000) -> 48
A6: FB000005 | B6: Tops | C6: Banana Republic | D6: Winter | E6: XL | F6: Black | G6: 105.02 | H6: 0 | I6: 105.02 | J6: 2025-08-06 | K6: 10 | M6: =FALSE() -> FALSE | O6: =IF(K6<=StockP33,"Low",IF(K6<=StockP67,"Moderate","High")) -> Low | P6: =IF(H6=0,"Low",IF(H6<=MarkdownP75,"Moderate","High")) -> Low | Q6: =IF(ISBLANK(L6),"Unknown",IF(L6>=4,"Good",IF(L6<=2,"Poor","Neutral"))) -> Unknown | R6: =IF(AND(O6="Low",P6="Low",Q6="Good"),"BUY / PRIORITIZE",IF(AND(O6="High",P6="High",OR(Q6="Poor",M6=TRUE())),"HOLD / REVIEW","MONITOR")) -> MONITOR | S6: =K6+(ROW()/10000000) -> 10.000001
A7: FB000006 | B7: Accessories | C7: Zara | D7: Fall | F7: White | G7: 35.03 | H7: 35.4 | I7: 22.63 | J7: 2025-08-06 | K7: 38 | L7: 2.9 | M7: =TRUE() -> TRUE | N7: Color Mismatch | O7: =IF(K7<=StockP33,"Low",IF(K7<=StockP67,"Moderate","High")) -> High | P7: =IF(H7=0,"Low",IF(H7<=MarkdownP75,"Moderate","High")) -> High | Q7: =IF(ISBLANK(L7),"Unknown",IF(L7>=4,"Good",IF(L7<=2,"Poor","Neutral"))) -> Neutral | R7: =IF(AND(O7="Low",P7="Low",Q7="Good"),"BUY / PRIORITIZE",IF(AND(O7="High",P7="High",OR(Q7="Poor",M7=TRUE())),"HOLD / REVIEW","MONITOR")) -> HOLD / REVIEW | S7: =K7+(ROW()/10000000) -> 38.000001
A8: FB000007 | B8: Bottoms | C8: Zara | D8: Spring | E8: S | F8: Gray | G8: 53.83 | H8: 54.5 | I8: 24.49 | J8: 2024-10-29 | K8: 38 | L8: 2.6 | M8: =FALSE() -> FALSE | O8: =IF(K8<=StockP33,"Low",IF(K8<=StockP67,"Moderate","High")) -> High | P8: =IF(H8=0,"Low",IF(H8<=MarkdownP75,"Moderate","High")) -> High | Q8: =IF(ISBLANK(L8),"Unknown",IF(L8>=4,"Good",IF(L8<=2,"Poor","Neutral"))) -> Neutral | R8: =IF(AND(O8="Low",P8="Low",Q8="Good"),"BUY / PRIORITIZE",IF(AND(O8="High",P8="High",OR(Q8="Poor",M8=TRUE())),"HOLD / REVIEW","MONITOR")) -> MONITOR | S8: =K8+(ROW()/10000000) -> 38.000001
A9: FB000008 | B9: Dresses | C9: Mango | D9: Winter | E9: XL | F9: Blue | G9: 91.55 | H9: 22.1 | I9: 71.32 | J9: 2025-08-06 | K9: 47 | L9: 1.6 | M9: =FALSE() -> FALSE | O9: =IF(K9<=StockP33,"Low",IF(K9<=StockP67,"Moderate","High")) -> High | P9: =IF(H9=0,"Low",IF(H9<=MarkdownP75,"Moderate","High")) -> Moderate | Q9: =IF(ISBLANK(L9),"Unknown",IF(L9>=4,"Good",IF(L9<=2,"Poor","Neutral"))) -> Poor | R9: =IF(AND(O9="Low",P9="Low",Q9="Good"),"BUY / PRIORITIZE",IF(AND(O9="High",P9="High",OR(Q9="Poor",M9=TRUE())),"HOLD / REVIEW","MONITOR")) -> MONITOR | S9: =K9+(ROW()/10000000) -> 47.000001
A10: FB000009 | B10: Outerwear | C10: Uniqlo | D10: Spring | E10: XL | F10: Green | G10: 227.73 | H10: 12.8 | I10: 198.58 | J10: 2025-03-24 | K10: 14 | M10: =FALSE() -> FALSE | O10: =IF(K10<=StockP33,"Low",IF(K10<=StockP67,"Moderate","High")) -> Low | P10: =IF(H10=0,"Low",IF(H10<=MarkdownP75,"Moderate","High")) -> Moderate | Q10: =IF(ISBLANK(L10),"Unknown",IF(L10>=4,"Good",IF(L10<=2,"Poor","Neutral"))) -> Unknown | R10: =IF(AND(O10="Low",P10="Low",Q10="Good"),"BUY / PRIORITIZE",IF(AND(O10="High",P10="High",OR(Q10="Poor",M10=TRUE())),"HOLD / REVIEW","MONITOR")) -> MONITOR | S10: =K10+(ROW()/10000000) -> 14.000001
A11: FB000010 | B11: Outerwear | C11: H&M | D11: Fall | E11: XXL | F11: Pink | G11: 248.41 | H11: 10.9 | I11: 221.33 | J11: 2025-08-06 | K11: 37 | M11: =FALSE() -> FALSE | O11: =IF(K11<=StockP33,"Low",IF(K11<=StockP67,"Moderate","High")) -> High | P11: =IF(H11=0,"Low",IF(H11<=MarkdownP75,"Moderate","High")) -> Moderate | Q11: =IF(ISBLANK(L11),"Unknown",IF(L11>=4,"Good",IF(L11<=2,"Poor","Neutral"))) -> Unknown | R11: =IF(AND(O11="Low",P11="Low",Q11="Good"),"BUY / PRIORITIZE",IF(AND(O11="High",P11="High",OR(Q11="Poor",M11=TRUE())),"HOLD / REVIEW","MONITOR")) -> MONITOR | S11: =K11+(ROW()/10000000) -> 37.000001
A12: FB000011 | B12: Tops | C12: Mango | D12: Spring | E12: L | F12: Black | G12: 116.84 | H12: 0 | I12: 116.84 | J12: 2025-04-25 | K12: 3 | L12: 4.4 | M12: =FALSE() -> FALSE | O12: =IF(K12<=StockP33,"Low",IF(K12<=StockP67,"Moderate","High")) -> Low | P12: =IF(H12=0,"Low",IF(H12<=MarkdownP75,"Moderate","High")) -> Low | Q12: =IF(ISBLANK(L12),"Unknown",IF(L12>=4,"Good",IF(L12<=2,"Poor","Neutral"))) -> Good | R12: =IF(AND(O12="Low",P12="Low",Q12="Good"),"BUY / PRIORITIZE",IF(AND(O12="High",P12="High",OR(Q12="Poor",M12=TRUE())),"HOLD / REVIEW","MONITOR")) -> BUY / PRIORITIZE | S12: =K12+(ROW()/10000000) -> 3.0000012
A13: FB000012 | B13: Shoes | C13: Uniqlo | D13: Winter | E13: S | F13: Blue | G13: 146.98 | H13: 0 | I13: 146.98 | J13: 2025-08-06 | K13: 2 | L13: 3.4 | M13: =FALSE() -> FALSE | O13: =IF(K13<=StockP33,"Low",IF(K13<=StockP67,"Moderate","High")) -> Low | P13: =IF(H13=0,"Low",IF(H13<=MarkdownP75,"Moderate","High")) -> Low | Q13: =IF(ISBLANK(L13),"Unknown",IF(L13>=4,"Good",IF(L13<=2,"Poor","Neutral"))) -> Neutral | R13: =IF(AND(O13="Low",P13="Low",Q13="Good"),"BUY / PRIORITIZE",IF(AND(O13="High",P13="High",OR(Q13="Poor",M13=TRUE())),"HOLD / REVIEW","MONITOR")) -> MONITOR | S13: =K13+(ROW()/10000000) -> 2.0000013
A14: FB000013 | B14: Bottoms | C14: Ann Taylor | D14: Spring | E14: S | F14: White | G14: 37.51 | H14: 0 | I14: 37.51 | J14: 2025-01-04 | K14: 43 | M14: =FALSE() -> FALSE | O14: =IF(K14<=StockP33,"Low",IF(K14<=StockP67,"Moderate","High")) -> High | P14: =IF(H14=0,"Low",IF(H14<=MarkdownP75,"Moderate","High")) -> Low | Q14: =IF(ISBLANK(L14),"Unknown",IF(L14>=4,"Good",IF(L14<=2,"Poor","Neutral"))) -> Unknown | R14: =IF(AND(O14="Low",P14="Low",Q14="Good"),"BUY / PRIORITIZE",IF(AND(O14="High",P14="High",OR(Q14="Poor",M14=TRUE())),"HOLD / REVIEW","MONITOR")) -> MONITOR | S14: =K14+(ROW()/10000000) -> 43.000001
A15: FB000014 | B15: Dresses | C15: Uniqlo | D15: Fall | E15: XS | F15: Beige | G15: 48.15 | H15: 0 | I15: 48.15 | J15: 2025-08-06 | K15: 39 | L15: 1.6 | M15: =FALSE() -> FALSE | O15: =IF(K15<=StockP33,"Low",IF(K15<=StockP67,"Moderate","High")) -> High | P15: =IF(H15=0,"Low",IF(H15<=MarkdownP75,"Moderate","High")) -> Low | Q15: =IF(ISBLANK(L15),"Unknown",IF(L15>=4,"Good",IF(L15<=2,"Poor","Neutral"))) -> Poor | R15: =IF(AND(O15="Low",P15="Low",Q15="Good"),"BUY / PRIORITIZE",IF(AND(O15="High",P15="High",OR(Q15="Poor",M15=TRUE())),"HOLD / REVIEW","MONITOR")) -> MONITOR | S15: =K15+(ROW()/10000000) -> 39.000002
A16: FB000015 | B16: Tops | C16: Mango | D16: Winter | E16: M | F16: Beige | G16: 79.66 | H16: 0 | I16: 79.66 | J16: 2025-08-06 | K16: 7 | L16: 1.7 | M16: =FALSE() -> FALSE | O16: =IF(K16<=StockP33,"Low",IF(K16<=StockP67,"Moderate","High")) -> Low | P16: =IF(H16=0,"Low",IF(H16<=MarkdownP75,"Moderate","High")) -> Low | Q16: =IF(ISBLANK(L16),"Unknown",IF(L16>=4,"Good",IF(L16<=2,"Poor","Neutral"))) -> Poor | R16: =IF(AND(O16="Low",P16="Low",Q16="Good"),"BUY / PRIORITIZE",IF(AND(O16="High",P16="High",OR(Q16="Poor",M16=TRUE())),"HOLD / REVIEW","MONITOR")) -> MONITOR | S16: =K16+(ROW()/10000000) -> 7.0000016
A17: FB000016 | B17: Accessories | C17: Mango | D17: Winter | F17: Green | G17: 67.57 | H17: 0 | I17: 67.57 | J17: 2025-08-06 | K17: 17 | L17: 2.4 | M17: =FALSE() -> FALSE | O17: =IF(K17<=StockP33,"Low",IF(K17<=StockP67,"Moderate","High")) -> Low | P17: =IF(H17=0,"Low",IF(H17<=MarkdownP75,"Moderate","High")) -> Low | Q17: =IF(ISBLANK(L17),"Unknown",IF(L17>=4,"Good",IF(L17<=2,"Poor","Neutral"))) -> Neutral | R17: =IF(AND(O17="Low",P17="Low",Q17="Good"),"BUY / PRIORITIZE",IF(AND(O17="High",P17="High",OR(Q17="Poor",M17=TRUE())),"HOLD / REVIEW","MONITOR")) -> MONITOR | S17: =K17+(ROW()/10000000) -> 17.000002
A18: FB000017 | B18: Shoes | C18: Gap | D18: Summer | E18: S | F18: Beige | G18: 123.53 | H18: 0 | I18: 123.53 | J18: 2025-08-06 | K18: 14 | L18: 4.6 | M18: =FALSE() -> FALSE | O18: =IF(K18<=StockP33,"Low",IF(K18<=StockP67,"Moderate","High")) -> Low | P18: =IF(H18=0,"Low",IF(H18<=MarkdownP75,"Moderate","High")) -> Low | Q18: =IF(ISBLANK(L18),"Unknown",IF(L18>=4,"Good",IF(L18<=2,"Poor","Neutral"))) -> Good | R18: =IF(AND(O18="Low",P18="Low",Q18="Good"),"BUY / PRIORITIZE",IF(AND(O18="High",P18="High",OR(Q18="Poor",M18=TRUE())),"HOLD / REVIEW","MONITOR")) -> BUY / PRIORITIZE | S18: =K18+(ROW()/10000000) -> 14.000002
A19: FB000018 | B19: Tops | C19: Ann Taylor | D19: Winter | E19: L | F19: Navy | G19: 102.35 | H19: 0 | I19: 102.35 | J19: 2025-08-06 | K19: 14 | L19: 3.5 | M19: =FALSE() -> FALSE | O19: =IF(K19<=StockP33,"Low",IF(K19<=StockP67,"Moderate","High")) -> Low | P19: =IF(H19=0,"Low",IF(H19<=MarkdownP75,"Moderate","High")) -> Low | Q19: =IF(ISBLANK(L19),"Unknown",IF(L19>=4,"Good",IF(L19<=2,"Poor","Neutral"))) -> Neutral | R19: =IF(AND(O19="Low",P19="Low",Q19="Good"),"BUY / PRIORITIZE",IF(AND(O19="High",P19="High",OR(Q19="Poor",M19=TRUE())),"HOLD / REVIEW","MONITOR")) -> MONITOR | S19: =K19+(ROW()/10000000) -> 14.000002
A20: FB000019 | B20: Outerwear | C20: Mango | D20: Summer | E20: M | F20: Purple | G20: 137.95 | H20: 58.5 | I20: 57.25 | J20: 2025-08-06 | K20: 16 | L20: 4.1 | M20: =FALSE() -> FALSE | O20: =IF(K20<=StockP33,"Low",IF(K20<=StockP67,"Moderate","High")) -> Low | P20: =IF(H20=0,"Low",IF(H20<=MarkdownP75,"Moderate","High")) -> High | Q20: =IF(ISBLANK(L20),"Unknown",IF(L20>=4,"Good",IF(L20<=2,"Poor","Neutral"))) -> Good | R20: =IF(AND(O20="Low",P20="Low",Q20="Good"),"BUY / PRIORITIZE",IF(AND(O20="High",P20="High",OR(Q20="Poor",M20=TRUE())),"HOLD / REVIEW","MONITOR")) -> MONITOR | S20: =K20+(ROW()/10000000) -> 16.000002
A21: FB000020 | B21: Outerwear | C21: Banana Republic | D21: Summer | E21: XXL | F21: Gray | G21: 142.59 | H21: 0 | I21: 142.59 | J21: 2025-08-06 | K21: 1 | L21: 3.7 | M21: =FALSE() -> FALSE | O21: =IF(K21<=StockP33,"Low",IF(K21<=StockP67,"Moderate","High")) -> Low | P21: =IF(H21=0,"Low",IF(H21<=MarkdownP75,"Moderate","High")) -> Low | Q21: =IF(ISBLANK(L21),"Unknown",IF(L21>=4,"Good",IF(L21<=2,"Poor","Neutral"))) -> Neutral | R21: =IF(AND(O21="Low",P21="Low",Q21="Good"),"BUY / PRIORITIZE",IF(AND(O21="High",P21="High",OR(Q21="Poor",M21=TRUE())),"HOLD / REVIEW","MONITOR")) -> MONITOR | S21: =K21+(ROW()/10000000) -> 1.0000021
A22: FB000021 | B22: Bottoms | C22: Mango | D22: Fall | E22: L | F22: Beige | G22: 33.33 | H22: 21.8 | I22: 26.06 | J22: 2025-08-06 | K22: 42 | M22: =FALSE() -> FALSE | O22: =IF(K22<=StockP33,"Low",IF(K22<=StockP67,"Moderate","High")) -> High | P22: =IF(H22=0,"Low",IF(H22<=MarkdownP75,"Moderate","High")) -> Moderate | Q22: =IF(ISBLANK(L22),"Unknown",IF(L22>=4,"Good",IF(L22<=2,"Poor","Neutral"))) -> Unknown | R22: =IF(AND(O22="Low",P22="Low",Q22="Good"),"BUY / PRIORITIZE",IF(AND(O22="High",P22="High",OR(Q22="Poor",M22=TRUE())),"HOLD / REVIEW","MONITOR")) -> MONITOR | S22: =K22+(ROW()/10000000) -> 42.000002
A23: FB000022 | B23: Accessories | C23: Zara | D23: Spring | F23: Brown | G23: 62.3 | H23: 0 | I23: 62.3 | J23: 2024-09-24 | K23: 10 | L23: 2.5 | M23: =FALSE() -> FALSE | O23: =IF(K23<=StockP33,"Low",IF(K23<=StockP67,"Moderate","High")) -> Low | P23: =IF(H23=0,"Low",IF(H23<=MarkdownP75,"Moderate","High")) -> Low | Q23: =IF(ISBLANK(L23),"Unknown",IF(L23>=4,"Good",IF(L23<=2,"Poor","Neutral"))) -> Neutral | R23: =IF(AND(O23="Low",P23="Low",Q23="Good"),"BUY / PRIORITIZE",IF(AND(O23="High",P23="High",OR(Q23="Poor",M23=TRUE())),"HOLD / REVIEW","MONITOR")) -> MONITOR | S23: =K23+(ROW()/10000000) -> 10.000002
A24: FB000023 | B24: Accessories | C24: Zara | D24: Winter | F24: Pink | G24: 38.48 | H24: 0 | I24: 38.48 | J24: 2025-08-06 | K24: 46 | L24: 1.2 | M24: =FALSE() -> FALSE | O24: =IF(K24<=StockP33,"Low",IF(K24<=StockP67,"Moderate","High")) -> High | P24: =IF(H24=0,"Low",IF(H24<=MarkdownP75,"Moderate","High")) -> Low | Q24: =IF(ISBLANK(L24),"Unknown",IF(L24>=4,"Good",IF(L24<=2,"Poor","Neutral"))) -> Poor | R24: =IF(AND(O24="Low",P24="Low",Q24="Good"),"BUY / PRIORITIZE",IF(AND(O24="High",P24="High",OR(Q24="Poor",M24=TRUE())),"HOLD / REVIEW","MONITOR")) -> MONITOR | S24: =K24+(ROW()/10000000) -> 46.000002
A25: FB000024 | B25: Dresses | C25: Banana Republic | D25: Summer | E25: XL | F25: Green | G25: 91.36 | H25: 0 | I25: 91.36 | J25: 2025-08-06 | K25: 37 | L25: 1.2 | M25: =TRUE() -> TRUE | N25: Size Issue | O25: =IF(K25<=StockP33,"Low",IF(K25<=StockP67,"Moderate","High")) -> High | P25: =IF(H25=0,"Low",IF(H25<=MarkdownP75,"Moderate","High")) -> Low | Q25: =IF(ISBLANK(L25),"Unknown",IF(L25>=4,"Good",IF(L25<=2,"Poor","Neutral"))) -> Poor | R25: =IF(AND(O25="Low",P25="Low",Q25="Good"),"BUY / PRIORITIZE",IF(AND(O25="High",P25="High",OR(Q25="Poor",M25=TRUE())),"HOLD / REVIEW","MONITOR")) -> MONITOR | S25: =K25+(ROW()/10000000) -> 37.000003
A26: FB000025 | B26: Tops | C26: Forever21 | D26: Fall | E26: XS | F26: Blue | G26: 80.47 | H26: 29.1 | I26: 57.05 | J26: 2025-08-06 | K26: 38 | L26: 3.6 | M26: =FALSE() -> FALSE | O26: =IF(K26<=StockP33,"Low",IF(K26<=StockP67,"Moderate","High")) -> High | P26: =IF(H26=0,"Low",IF(H26<=MarkdownP75,"Moderate","High")) -> High | Q26: =IF(ISBLANK(L26),"Unknown",IF(L26>=4,"Good",IF(L26<=2,"Poor","Neutral"))) -> Neutral | R26: =IF(AND(O26="Low",P26="Low",Q26="Good"),"BUY / PRIORITIZE",IF(AND(O26="High",P26="High",OR(Q26="Poor",M26=TRUE())),"HOLD / REVIEW","MONITOR")) -> MONITOR | S26: =K26+(ROW()/10000000) -> 38.000003
A27: FB000026 | B27: Bottoms | C27: Uniqlo | D27: Spring | E27: M | F27: Red | G27: 40.89 | H27: 34 | I27: 26.99 | J27: 2025-06-11 | K27: 16 | L27: 3.7 | M27: =FALSE() -> FALSE | O27: =IF(K27<=StockP33,"Low",IF(K27<=StockP67,"Moderate","High")) -> Low | P27: =IF(H27=0,"Low",IF(H27<=MarkdownP75,"Moderate","High")) -> High | Q27: =IF(ISBLANK(L27),"Unknown",IF(L27>=4,"Good",IF(L27<=2,"Poor","Neutral"))) -> Neutral | R27: =IF(AND(O27="Low",P27="Low",Q27="Good"),"BUY / PRIORITIZE",IF(AND(O27="High",P27="High",OR(Q27="Poor",M27=TRUE())),"HOLD / REVIEW","MONITOR")) -> MONITOR | S27: =K27+(ROW()/10000000) -> 16.000003
A28: FB000027 | B28: Bottoms | C28: Banana Republic | D28: Summer | E28: L | F28: Red | G28: 47.04 | H28: 36 | I28: 30.11 | J28: 2025-08-06 | K28: 25 | L28: 1.1 | M28: =TRUE() -> TRUE | N28: Damaged | O28: =IF(K28<=StockP33,"Low",IF(K28<=StockP67,"Moderate","High")) -> Moderate | P28: =IF(H28=0,"Low",IF(H28<=MarkdownP75,"Moderate","High")) -> High | Q28: =IF(ISBLANK(L28),"Unknown",IF(L28>=4,"Good",IF(L28<=2,"Poor","Neutral"))) -> Poor | R28: =IF(AND(O28="Low",P28="Low",Q28="Good"),"BUY / PRIORITIZE",IF(AND(O28="High",P28="High",OR(Q28="Poor",M28=TRUE())),"HOLD / REVIEW","MONITOR")) -> MONITOR | S28: =K28+(ROW()/10000000) -> 25.000003
A29: FB000028 | B29: Bottoms | C29: Gap | D29: Summer | E29: M | F29: Blue | G29: 53.37 | H29: 0 | I29: 53.37 | J29: 2025-08-06 | K29: 28 | L29: 3.8 | M29: =FALSE() -> FALSE | O29: =IF(K29<=StockP33,"Low",IF(K29<=StockP67,"Moderate","High")) -> Moderate | P29: =IF(H29=0,"Low",IF(H29<=MarkdownP75,"Moderate","High")) -> Low | Q29: =IF(ISBLANK(L29),"Unknown",IF(L29>=4,"Good",IF(L29<=2,"Poor","Neutral"))) -> Neutral | R29: =IF(AND(O29="Low",P29="Low",Q29="Good"),"BUY / PRIORITIZE",IF(AND(O29="High",P29="High",OR(Q29="Poor",M29=TRUE())),"HOLD / REVIEW","MONITOR")) -> MONITOR | S29: =K29+(ROW()/10000000) -> 28.000003
A30: FB000029 | B30: Dresses | C30: Ann Taylor | D30: Summer | E30: L | F30: White | G30: 114.35 | H30: 0 | I30: 114.35 | J30: 2025-08-06 | K30: 6 | L30: 1.2 | M30: =FALSE() -> FALSE | O30: =IF(K30<=StockP33,"Low",IF(K30<=StockP67,"Moderate","High")) -> Low | P30: =IF(H30=0,"Low",IF(H30<=MarkdownP75,"Moderate","High")) -> Low | Q30: =IF(ISBLANK(L30),"Unknown",IF(L30>=4,"Good",IF(L30<=2,"Poor","Neutral"))) -> Poor | R30: =IF(AND(O30="Low",P30="Low",Q30="Good"),"BUY / PRIORITIZE",IF(AND(O30="High",P30="High",OR(Q30="Poor",M30=TRUE())),"HOLD / REVIEW","MONITOR")) -> MONITOR | S30: =K30+(ROW()/10000000) -> 6.000003
A31: FB000030 | B31: Shoes | C31: Gap | D31: Spring | E31: XL | F31: Red | G31: 77.63 | H31: 0 | I31: 77.63 | J31: 2024-10-24 | K31: 1 | M31: =FALSE() -> FALSE | O31: =IF(K31<=StockP33,"Low",IF(K31<=StockP67,"Moderate","High")) -> Low | P31: =IF(H31=0,"Low",IF(H31<=MarkdownP75,"Moderate","High")) -> Low | Q31: =IF(ISBLANK(L31),"Unknown",IF(L31>=4,"Good",IF(L31<=2,"Poor","Neutral"))) -> Unknown | R31: =IF(AND(O31="Low",P31="Low",Q31="Good"),"BUY / PRIORITIZE",IF(AND(O31="High",P31="High",OR(Q31="Poor",M31=TRUE())),"HOLD / REVIEW","MONITOR")) -> MONITOR | S31: =K31+(ROW()/10000000) -> 1.0000031
A32: FB000031 | B32: Shoes | C32: Uniqlo | D32: Summer | E32: S | F32: Red | G32: 71.29 | H32: 0 | I32: 71.29 | J32: 2025-08-06 | K32: 37 | L32: 4.1 | M32: =TRUE() -> TRUE | N32: Quality Issue | O32: =IF(K32<=StockP33,"Low",IF(K32<=StockP67,"Moderate","High")) -> High | P32: =IF(H32=0,"Low",IF(H32<=MarkdownP75,"Moderate","High")) -> Low | Q32: =IF(ISBLANK(L32),"Unknown",IF(L32>=4,"Good",IF(L32<=2,"Poor","Neutral"))) -> Good | R32: =IF(AND(O32="Low",P32="Low",Q32="Good"),"BUY / PRIORITIZE",IF(AND(O32="High",P32="High",OR(Q32="Poor",M32=TRUE())),"HOLD / REVIEW","MONITOR")) -> MONITOR | S32: =K32+(ROW()/10000000) -> 37.000003
A33: FB000032 | B33: Tops | C33: Gap | D33: Spring | E33: L | F33: Purple | G33: 37.43 | H33: 24.4 | I33: 28.3 | J33: 2025-04-16 | K33: 5 | M33: =FALSE() -> FALSE | O33: =IF(K33<=StockP33,"Low",IF(K33<=StockP67,"Moderate","High")) -> Low | P33: =IF(H33=0,"Low",IF(H33<=MarkdownP75,"Moderate","High")) -> High | Q33: =IF(ISBLANK(L33),"Unknown",IF(L33>=4,"Good",IF(L33<=2,"Poor","Neutral"))) -> Unknown | R33: =IF(AND(O33="Low",P33="Low",Q33="Good"),"BUY / PRIORITIZE",IF(AND(O33="High",P33="High",OR(Q33="Poor",M33=TRUE())),"HOLD / REVIEW","MONITOR")) -> MONITOR | S33: =K33+(ROW()/10000000) -> 5.0000033
A34: FB000033 | B34: Shoes | C34: Zara | D34: Spring | E34: XL | F34: Purple | G34: 143.78 | H34: 0 | I34: 143.78 | J34: 2024-10-16 | K34: 43 | L34: 1.1 | M34: =FALSE() -> FALSE | O34: =IF(K34<=StockP33,"Low",IF(K34<=StockP67,"Moderate","High")) -> High | P34: =IF(H34=0,"Low",IF(H34<=MarkdownP75,"Moderate","High")) -> Low | Q34: =IF(ISBLANK(L34),"Unknown",IF(L34>=4,"Good",IF(L34<=2,"Poor","Neutral"))) -> Poor | R34: =IF(AND(O34="Low",P34="Low",Q34="Good"),"BUY / PRIORITIZE",IF(AND(O34="High",P34="High",OR(Q34="Poor",M34=TRUE())),"HOLD / REVIEW","MONITOR")) -> MONITOR | S34: =K34+(ROW()/10000000) -> 43.000003
A35: FB000034 | B35: Tops | C35: Banana Republic | D35: Summer | E35: XL | F35: Gray | G35: 88.23 | H35: 0 | I35: 88.23 | J35: 2025-08-06 | K35: 44 | L35: 1.6 | M35: =FALSE() -> FALSE | O35: =IF(K35<=StockP33,"Low",IF(K35<=StockP67,"Moderate","High")) -> High | P35: =IF(H35=0,"Low",IF(H35<=MarkdownP75,"Moderate","High")) -> Low | Q35: =IF(ISBLANK(L35),"Unknown",IF(L35>=4,"Good",IF(L35<=2,"Poor","Neutral"))) -> Poor | R35: =IF(AND(O35="Low",P35="Low",Q35="Good"),"BUY / PRIORITIZE",IF(AND(O35="High",P35="High",OR(Q35="Poor",M35=TRUE())),"HOLD / REVIEW","MONITOR")) -> MONITOR | S35: =K35+(ROW()/10000000) -> 44.000003
A36: FB000035 | B36: Accessories | C36: Forever21 | D36: Fall | F36: Navy | G36: 58.57 | H36: 0 | I36: 58.57 | J36: 2025-08-06 | K36: 38 | L36: 1.5 | M36: =FALSE() -> FALSE | O36: =IF(K36<=StockP33,"Low",IF(K36<=StockP67,"Moderate","High")) -> High | P36: =IF(H36=0,"Low",IF(H36<=MarkdownP75,"Moderate","High")) -> Low | Q36: =IF(ISBLANK(L36),"Unknown",IF(L36>=4,"Good",IF(L36<=2,"Poor","Neutral"))) -> Poor | R36: =IF(AND(O36="Low",P36="Low",Q36="Good"),"BUY / PRIORITIZE",IF(AND(O36="High",P36="High",OR(Q36="Poor",M36=TRUE())),"HOLD / REVIEW","MONITOR")) -> MONITOR | S36: =K36+(ROW()/10000000) -> 38.000004
A37: FB000036 | B37: Tops | C37: Uniqlo | D37: Winter | E37: XXL | F37: White | G37: 119.7 | H37: 5.7 | I37: 112.88 | J37: 2025-08-06 | K37: 37 | L37: 4.9 | M37: =FALSE() -> FALSE | O37: =IF(K37<=StockP33,"Low",IF(K37<=StockP67,"Moderate","High")) -> High | P37: =IF(H37=0,"Low",IF(H37<=MarkdownP75,"Moderate","High")) -> Moderate | Q37: =IF(ISBLANK(L37),"Unknown",IF(L37>=4,"Good",IF(L37<=2,"Poor","Neutral"))) -> Good | R37: =IF(AND(O37="Low",P37="Low",Q37="Good"),"BUY / PRIORITIZE",IF(AND(O37="High",P37="High",OR(Q37="Poor",M37=TRUE())),"HOLD / REVIEW","MONITOR")) -> MONITOR | S37: =K37+(ROW()/10000000) -> 37.000004
A38: FB000037 | B38: Bottoms | C38: Banana Republic | D38: Fall | E38: XXL | F38: Green | G38: 97.06 | H38: 47.8 | I38: 50.67 | J38: 2025-08-06 | K38: 31 | L38: 4.1 | M38: =FALSE() -> FALSE | O38: =IF(K38<=StockP33,"Low",IF(K38<=StockP67,"Moderate","High")) -> Moderate | P38: =IF(H38=0,"Low",IF(H38<=MarkdownP75,"Moderate","High")) -> High | Q38: =IF(ISBLANK(L38),"Unknown",IF(L38>=4,"Good",IF(L38<=2,"Poor","Neutral"))) -> Good | R38: =IF(AND(O38="Low",P38="Low",Q38="Good"),"BUY / PRIORITIZE",IF(AND(O38="High",P38="High",OR(Q38="Poor",M38=TRUE())),"HOLD / REVIEW","MONITOR")) -> MONITOR | S38: =K38+(ROW()/10000000) -> 31.000004
A39: FB000038 | B39: Dresses | C39: Banana Republic | D39: Summer | E39: L | F39: White | G39: 110.09 | H39: 0 | I39: 110.09 | J39: 2025-08-06 | K39: 32 | L39: 3.4 | M39: =FALSE() -> FALSE | O39: =IF(K39<=StockP33,"Low",IF(K39<=StockP67,"Moderate","High")) -> Moderate | P39: =IF(H39=0,"Low",IF(H39<=MarkdownP75,"Moderate","High")) -> Low | Q39: =IF(ISBLANK(L39),"Unknown",IF(L39>=4,"Good",IF(L39<=2,"Poor","Neutral"))) -> Neutral | R39: =IF(AND(O39="Low",P39="Low",Q39="Good"),"BUY / PRIORITIZE",IF(AND(O39="High",P39="High",OR(Q39="Poor",M39=TRUE())),"HOLD / REVIEW","MONITOR")) -> MONITOR | S39: =K39+(ROW()/10000000) -> 32.000004
A40: FB000039 | B40: Shoes | C40: Zara | D40: Winter | E40: XS | F40: Green | G40: 198.42 | H40: 14.2 | I40: 170.24 | J40: 2025-08-06 | K40: 10 | M40: =FALSE() -> FALSE | O40: =IF(K40<=StockP33,"Low",IF(K40<=StockP67,"Moderate","High")) -> Low | P40: =IF(H40=0,"Low",IF(H40<=MarkdownP75,"Moderate","High")) -> Moderate | Q40: =IF(ISBLANK(L40),"Unknown",IF(L40>=4,"Good",IF(L40<=2,"Poor","Neutral"))) -> Unknown | R40: =IF(AND(O40="Low",P40="Low",Q40="Good"),"BUY / PRIORITIZE",IF(AND(O40="High",P40="High",OR(Q40="Poor",M40=TRUE())),"HOLD / REVIEW","MONITOR")) -> MONITOR | S40: =K40+(ROW()/10000000) -> 10.000004
...

Sheet Assumptions
A1: Assumption | B1: Value
A2: Stock P33 (tercile cutoff) | B2: =PERCENTILE('Raw Data'!$K$2:$K$2177,1/3) -> 17
A3: Stock P67 (tercile cutoff) | B3: =PERCENTILE('Raw Data'!$K$2:$K$2177,2/3) -> 33
A4: Markdown P75 (High cutoff) | B4: =PERCENTILE('Raw Data'!$H$2:$H$2177,0.75) -> 22.425
A5: Overall Avg Markdown % | B5: =AVERAGE('Raw Data'!$H$2:$H$2177) -> 12.144715
A6: Overall Return Rate | B6: =SUMPRODUCT(--('Raw Data'!$M$2:$M$2177))/COUNTA('Raw Data'!$M$2:$M$2177) -> 0.14705882
A7: Total Inventory | B7: =SUM('Raw Data'!$K$2:$K$2177) -> 54265
A8: Total Products | B8: =COUNTA('Raw Data'!$A$2:$A$2177) -> 2176
A9: Avg Current Price | B9: =AVERAGE('Raw Data'!$I$2:$I$2177) -> 85.499596
